Workbook

Sheet WL-Single Gable-MBS
A1: Load Calculation Sheet
A2: Project | C2: Nahar Industries Enterprises Ltd. | H2: Support | I2: Fix
A3: Building | H3: EQ Zone | I3: IV
H4: DL | I4: 0.15 | J4: kN / sqm
A5: L-Length of building (Greater hoz dim. Of bldg.) | E5: meters | F5: 72 | H5: LL | I5: 0.57 | J5: kN / sqm
A6: w-Width of building Lesser hoz dim. Of bldg.) | E6: m | F6: 22.015 | H6: CL | I6: 0 | J6: kN / sqm
A7: h1-Height of plinth | E7: m | F7: 0 | H7: Trib Sidewall | I7: 6 | J7: M
A8: h2-Eaves height from FFL | E8: m | F8: 28.5 | H8: Openings | I8: <5%
A9: h3-Height of ridge above eves | E9: m | F9: 4.5
A10: h-Eaves height from FGL | E10: m | F10: =F7+F8 -> 28.5 | H10: Trib Endwall | I10: 7.2 | J10: M
A12: Roof Slope | E12: 1 | F12: 10
A13: Vb-Basic wind speed | E13: m/sec | F13: 39
A14: N-Design life of structure; mean probable | E14: Years | F14: 50
A15: Terrain Category | F15: 2
A16: Category1- Exposed open terrain with few or no obstructions having heights less than 1.5m.
A17: Category2- Open terrain with well scattered obstructions having heights between 1.5m.& 10m.
A18: Category3- Terrain with numerous closely spaced obstructions having heights around 10m.
A19: Category4- Terrain with numerous closely spaced high obstructions
A21: Class of Building | F21: C
A22: Class-A - Structure & or compo like cladding, roofing etc having greatest Hoz Or Vert dim < 20m.
A23: Class-B - Structure & or compo like cladding, roofing etc having greatest Hoz Or Vert dim bet 20-50
A24: Class-C - Structure & or compo like cladding, roofing etc having greatest Hoz Or Vert dim > 50m.
A26: Table-1-IS 875 (Part3)-1987
A27: K1-Risk Coeff.
E28: Vb | F28: A | G28: B
E29: 33 | F29: 83.2 | G29: 9.2
E30: 39 | F30: 84 | G30: 14
E31: 44 | F31: 88 | G31: 18
E32: 47 | F32: 88 | G32: 20.5
E33: 50 | F33: 88.8 | G33: 22.8
E34: 55 | F34: 90.8 | G34: 27.3
A35: PN | F35: 0.63
A36: A = | F36: =VLOOKUP(F13,E29:G34,2) -> 84
A37: B = | F37: =VLOOKUP(F13,E29:G34,3) -> 14
A39: K1-Risk Coeff. | F39: 1
A40: HT Max Height of building from FGL | E40: m | F40: =F10 -> 28.5
A42: Table 2-IS-875 (Part3) 1987
A43: K2-Terrain,Str-height &size factor | E43: Category | F43: 2 | N43: Ka | P43: 10 | Q43: 1 | S43: 10 | T43: 1
E44: HT | F44: A
E45: 0 | F45: 1.05
...

Sheet Sheet1
A1: Building Length (Longer dim) (l) = | B1: =+'WL-Single Gable-MBS'!F5 -> 72 | C1: m
A2: Width O/O (Shorter Dim) (w) = | B2: =+'WL-Single Gable-MBS'!F6 -> 22.015 | C2: m
A3: Eave Height (h)= | B3: 7 | C3: m
A4: Roof Slope = | B4: 1 | C4: in | D4: 10
A6: Basic Wind Speed Vb = | B6: ='WL-Single Gable-MBS'!F13 -> 39 | C6: m/s
A8: Probability Factor k1= | B8: 1
A9: Terrain, ht & structure size factor k2= | B9: ='WL-Single Gable-MBS'!F146 -> 1.1125
A10: Topography Factor k3 = | B10: 1
A12: Design Wind Speed Vz = | B12: =B6*B8*B9*B10 -> 43.3875 | C12: m/s
A14: Design wind pressure pz = | B14: =+'WL-Single Gable-MBS'!F152 -> 0.79063957 | C14: Kn/m2
A16: Framed opening area = | B16: 20
A17: Load Tributary / sidewall Spacing = | B17: ='WL-Single Gable-MBS'!I7 -> 6 | C17: m
A18: Load Tributary / Endwall Spacing = | B18: ='WL-Single Gable-MBS'!I10 -> 7.2 | C18: m
A19: Internal Pressure Coefficient Calculation Cpi
A21: Roof angle= | B21: =ATAN(B4/D4)*180/PI() -> 5.7105931 | C21: Degrees | O21: External Pressure Coefficient for walls of rectangular clad building
A22: Ridge Height = | B22: =B2/2*B4/D4+B3 -> 8.10075
A23: Endwall wall area = | B23: =2*B2*B3+(B22-B3)*B2 -> 332.44301 | O23: h/w | P23: L/w | Q23: Wind Angle | R23: A | S23: B | T23: C | U23: D | V23: Local
A24: Sidewall area = | B24: =2*B1*B3 -> 1008 | P24: 1-1.5 | Q24: 0o | R24: 0.7 | S24: -0.2 | T24: -0.5 | U24: -0.5 | V24: -0.8
A25: Total wall area= | B25: =B23+B24 -> 1340.443 | Q25: 90o | R25: -0.5 | S25: -0.5 | T25: 0.7 | U25: -0.2 | V25: -0.8
A26: Percentage of openings = | B26: =B16/B25*100 -> 1.492044 | C26: % | O26: 0.5
A27: Hence Cpe = | B27: =+'WL-Single Gable-MBS'!F270 -> 0.2 | P27: 1.5-4.0 | Q27: 0o | R27: 0.7 | S27: -0.25 | T27: -0.6 | U27: -0.6 | V27: -1
Q28: 90o | R28: -0.5 | S28: -0.5 | T28: 0.7 | U28: -0.1 | V28: -1
A29: External Pressure Coefficient Calculation Cpe
P30: 1-1.5 | Q30: 0o | R30: 0.7 | S30: -0.25 | T30: -0.6 | U30: -0.6 | V30: -1.1
A31: h/w = | B31: =+'WL-Single Gable-MBS'!F161 -> 1.2945719 | Q31: 90o | R31: -0.6 | S31: -0.6 | T31: 0.7 | U31: -0.25 | V31: -1.1
A32: L/w = | B32: =+'WL-Single Gable-MBS'!F162 -> 3.2704974 | O32: 0.5-1.5
P33: 1.5-4.0 | Q33: 0o | R33: 0.7 | S33: -0.3 | T33: -0.7 | U33: -0.7 | V33: -1.1
A34: External Pressure Coefficient for Wall of rectangular Clad building | Q34: 90o | R34: -0.5 | S34: -0.5 | T34: 0.7 | U34: -0.1 | V34: -1.1
A35: For Wind Angle 0 Degree
A36: A = | B36: =IF($B$31<=0.5,IF($B$32<=1.5,R24,R27),IF($B$31<=1.5,IF($B$32<=1.5,R30,R33),IF($B$31<=6,IF($B$32<=1.5,R36,R39),IF($B$32<=1,R42,IF($B$32<=1.5,R45,R48))))) -> 0.7 | D36: C = | E36: =IF($B$31<=0.5,IF($B$32<=1.5,T24,T27),IF($B$31<=1.5,IF($B$32<=1.5,T30,T33),IF($B$31<=6,IF($B$32<=1.5,T36,T39),IF($B$32<=1,T42,IF($B$32<=1.5,T45,T48))))) -> -0.7 | P36: 1-1.5 | Q36: 0o | R36: 0.8 | S36: -0.25 | T36: -0.8 | U36: -0.8 | V36: -1.2
A37: B = | B37: =IF($B$31<=0.5,IF($B$32<=1.5,S24,S27),IF($B$31<=1.5,IF($B$32<=1.5,S30,S33),IF($B$31<=6,IF($B$32<=1.5,S36,S39),IF($B$32<=1,S42,IF($B$32<=1.5,S45,S48))))) -> -0.3 | D37: D = | E37: =IF($B$31<=0.5,IF($B$32<=1.5,U24,U27),IF($B$31<=1.5,IF($B$32<=1.5,U30,U33),IF($B$31<=6,IF($B$32<=1.5,U36,U39),IF($B$32<=1,U42,IF($B$32<=1.5,U45,U48))))) -> -0.7 | Q37: 90o | R37: -0.8 | S37: -0.8 | T37: 0.8 | U37: -0.25 | V37: -1.2
O38: 1.5-6.0
A39: For Wind Angle 90 Degree | P39: 1.5-4.0 | Q39: 0o | R39: 0.7 | S39: -0.4 | T39: -0.7 | U39: -0.7 | V39: -1.2
A40: A = | B40: =IF($B$31<=0.5,IF($B$32<=1.5,R25,R28),IF($B$31<=1.5,IF($B$32<=1.5,R31,R34),IF($B$31<=6,IF($B$32<=1.5,R37,R40),IF($B$32<=1,R43,IF($B$32<=1.5,R46,R49))))) -> -0.5 | D40: C = | E40: =IF($B$31<=0.5,IF($B$32<=1.5,T25,T28),IF($B$31<=1.5,IF($B$32<=1.5,T31,T34),IF($B$31<=6,IF($B$32<=1.5,T37,T40),IF($B$32<=1,T43,IF($B$32<=1.5,T46,T49))))) -> 0.7 | Q40: 90o | R40: -0.5 | S40: -0.5 | T40: 0.8 | U40: -0.1 | V40: -1.2
A41: B = | B41: =IF($B$31<=0.5,IF($B$32<=1.5,S25,S28),IF($B$31<=1.5,IF($B$32<=1.5,S31,S34),IF($B$31<=6,IF($B$32<=1.5,S37,S40),IF($B$32<=1,S43,IF($B$32<=1.5,S46,S49))))) -> -0.5 | D41: D = | E41: =IF($B$31<=0.5,IF($B$32<=1.5,U25,U28),IF($B$31<=1.5,IF($B$32<=1.5,U31,U34),IF($B$31<=6,IF($B$32<=1.5,U37,U40),IF($B$32<=1,U43,IF($B$32<=1.5,U46,U49))))) -> -0.1
P42: 1.5 | Q42: 0o | R42: 0.95 | S42: -1.85 | T42: -0.9 | U42: -0.9 | V42: -1.25
A43: External Pressure Coefficient for Roof of rectangular Clad building | Q43: 90o | R43: -0.8 | S43: -0.8 | T43: 0.9 | U43: -0.85 | V43: -1.25
A45: For Wind Angle 0 Degree | O45: 6.0-α. | P45: 1 | Q45: 0o | R45: 0.95 | S45: -1.25 | T45: -0.7 | U45: -0.7 | V45: -1.25
A46: Near Roof Plane = | B46: =ROUNDUP(+'WL-Single Gable-MBS'!D264,3) -> -0.929 | Q46: 90o | R46: -0.7 | S46: -0.7 | T46: 0.95 | U46: -1.25 | V46: -1.25
A47: Far Roof Plane = | B47: =+'WL-Single Gable-MBS'!E264 -> -0.6
...

Sheet For STAAD
B2: Staad output
B4: Enter the Tributary area on frames in mts | E4: ='WL-Single Gable-MBS'!I7 -> 6
B6: Enter the 1st load combination number for wind load | E6: 7
B7: Enter the member ids for Left column | E7: 1 | I7: 21 59 60 67 TO 70
B8: Enter the member ids for Left rafter | E8: 3
B9: Enter the member ids for Right rafter | E9: 4
B10: Enter the member ids for Right column | E10: 2
B12: WIND LOAD CASES
B13: ************WIND PRESSURE LEFT TO RIGHT*********
B14: =CONCATENATE("LOAD ", E6," LOADTYPE Wind TITLE WL1") -> LOAD 7 LOADTYPE Wind TITLE WL1
B15: MEMBER LOAD
B16: =$E$7 -> 1 | C16: UNI | D16: GX | E16: =Sheet1!B59 -> 2.3719187
B17: =$E$8 -> 3 | C17: UNI | D17: Y | E17: =-Sheet1!B61 -> 5.3557924
B18: =$E$9 -> 4 | C18: UNI | D18: Y | E18: =-Sheet1!B62 -> 3.7950699
B19: =$E$10 -> 2 | C19: UNI | D19: GX | E19: =-Sheet1!B60 -> 2.3719187
B22: ************WIND PRESSURE RIGHT TO LEFT*********
B23: =CONCATENATE("LOAD ", $E$6+1," LOADTYPE Wind TITLE WL2") -> LOAD 8 LOADTYPE Wind TITLE WL2
B24: MEMBER LOAD
B25: =$E$7 -> 1 | C25: UNI | D25: GX | E25: =Sheet1!B77 -> -2.3719187
B26: =$E$8 -> 3 | C26: UNI | D26: Y | E26: =-Sheet1!B79 -> 3.7950699
B27: =$E$9 -> 4 | C27: UNI | D27: Y | E27: =-Sheet1!B80 -> 5.3557924
B28: =$E$10 -> 2 | C28: UNI | D28: GX | E28: =-Sheet1!B78 -> -2.3719187
B31: ************WIND SUCTION LEFT TO RIGHT*********
B32: =CONCATENATE("LOAD ", $E$6+2," LOADTYPE Wind TITLE WL3") -> LOAD 9 LOADTYPE Wind TITLE WL3
B33: MEMBER LOAD
B34: =$E$7 -> 1 | C34: UNI | D34: GX | E34: =Sheet1!B68 -> 4.2694537
B35: =$E$8 -> 3 | C35: UNI | D35: Y | E35: =-Sheet1!B70 -> 3.4582575
B36: =$E$9 -> 4 | C36: UNI | D36: Y | E36: =-Sheet1!B71 -> 1.897535
B37: =$E$10 -> 2 | C37: UNI | D37: GX | E37: =-Sheet1!B69 -> 0.47438374
B40: ************WIND SUCTION RIGHT TO LEFT*********
B41: =CONCATENATE("LOAD ", $E$6+3," LOADTYPE Wind TITLE WL4") -> LOAD 10 LOADTYPE Wind TITLE WL4
B42: MEMBER LOAD
B43: =$E$7 -> 1 | C43: UNI | D43: GX | E43: =Sheet1!B86 -> -0.47438374
B44: =$E$8 -> 3 | C44: UNI | D44: Y | E44: =-Sheet1!B88 -> 1.897535
B45: =$E$9 -> 4 | C45: UNI | D45: Y | E45: =-Sheet1!B89 -> 3.4582575
B46: =$E$10 -> 2 | C46: UNI | D46: GX | E46: =-Sheet1!B87 -> -4.2694537
B49: ************WIND PARALLEL PRESSURE GABLE-1*********
B50: =CONCATENATE("LOAD ", $E$6+4," LOADTYPE Wind TITLE WL5") -> LOAD 11 LOADTYPE Wind TITLE WL5
B51: MEMBER LOAD
B52: =$E$7 -> 1 | C52: UNI | D52: GX | E52: =Sheet1!B95 -> -3.3206862
...
